Workbook
Name Slicer_Department: #N/A
Name Slicer_Manager_Name: #N/A
Name Slicer_Risk_Band: #N/A

Sheet RAW_Data
A1: EmpID | B1: Full Name | C1: Department | D1: Hire Date | E1: Date of Birth | F1: Last Promotion Date | G1: Performance Rating (1-5) | H1: Manager ID | I1: Monthly Salary | J1: Status | K1: Gender | L1: City
A2: EMP2824 | B2: Priya Trivedi | C2: Marketing | D2: 05/04/2013 | E2: 22/02/1968 | F2: 19-02-2018 | G2: 3 | H2: M01 | I2: 46000 | J2: active | K2: Male | L2: Delhi
A3: EMP1106 | B3: Kapil Pandey | C3: IT | D3: 05-05-2015 | E3: 04 Jun 1987 | F3: 04/07/2016 | G3: 3 | H3: M06 | I3: 112000 | J3: ACTIVE | K3: Female | L3: Kolkata
A4: EMP6925 | B4: Pranav Agarwal | C4: Engineering | D4: 11/08/2010 | E4: 1979-02-28 | F4: 13-02-2012 | G4: 3 | H4: M06 | I4: 55000 | J4: Active | K4: Female | L4: Bangalore
A5: EMP4598 | B5: Geeta Goel | C5: Sales | D5: 26 Jan 2013 | E5: 07/09/1981 | F5: 2014-04-19 | G5: 5 | H5: M06 | I5: 62000 | J5: active | K5: Female | L5: Chennai
A6: EMP6930 | B6: Suresh Mishra | C6: Legal | D6: 2011-01-28 | E6: 21/03/1986 | F6: 14-11-2013 | G6: 4 | H6: M07 | I6: 83000 | J6: Active | K6: F | L6: Hyderabad
A7: EMP5808 | B7: Neha Pandey | C7: Legal | D7: 2010-12-24 | E7: 09/25/1980 | F7: 04/09/2012 | G7: 5 | H7: M05 | I7: 142000 | J7: ACTIVE | K7: M | L7: Delhi
A8: EMP6947 | B8: Ritu Srivastava | C8: Sales | D8: 03/10/2013 | E8: 16/12/1989 | F8: 25 Sep 2014 | G8: 2 | H8: M08 | I8: 105000 | J8: ACTIVE | K8: M | L8: Bangalore
A9: EMP7118 | B9: Alok Dutta | C9: Legal | D9: 08-04-2011 | E9: 01-06-1987 | F9: 2016-09-08 | G9: 4 | H9: M01 | I9: Rs.44000 | J9: Active | K9: Male | L9: Delhi
A10: EMP8744 | B10: Kavya Subramaniam | C10: IT | D10: 04 Feb 2013 | E10: 1970-07-12 | F10: 15-07-2017 | G10: 5 | H10: M01 | I10: 121000 | J10: Active | K10: Male | L10: Mumbai
A11: EMP2235 | B11: Alok Ghosh | C11: Engineering | D11: 11/18/2010 | E11: 25 Feb 1988 | F11: 14-03-2012 | G11: 3 | H11: M04 | I11: 145000 | J11: Active | K11: F | L11: Mumbai
A12: EMP8973 | B12: Pooja Agarwal | C12: Marketing | D12: 01/19/2013 | E12: 02-09-1968 | F12: 02/01/2016 | G12: 4 | H12: M03 | I12: Rs.42000 | J12: ACTIVE | K12: Male | L12: Kolkata
A13: EMP1651 | B13: Usha Joshi | C13: IT | D13: 2020-10-19 | E13: 09 Jun 1982 | F13: 2022-11-23 | G13: 3 | H13: M05 | I13: 85000 | J13: ACTIVE | K13: Male | L13: Pune
A14: EMP9808 | B14: Nisha Das | C14: Marketing | D14: 03/06/2012 | E14: 1983-06-10 | F14: 27-08-2014 | G14: 4 | H14: M05 | I14: 113000 | J14: Active | K14: Male | L14: Pune
A15: EMP4450 | B15: Mala Bhatia | D15: 11/28/2020 | E15: 1990-09-16 | F15: 01/03/2023 | G15: 4 | H15: M05 | I15: 40000 | J15: Active | K15: Male | L15: Bangalore
A16: EMP3442 | B16: Vikas Singh | C16: Operations | D16: 09/05/2019 | E16: 02-03-1984 | F16: 2022-06-26 | G16: 5 | H16: M01 | I16: 150000 | J16: ACTIVE | K16: Female | L16: Delhi
A17: EMP3662 | B17: Divya Pillai | C17: Sales | D17: 11 Dec 2012 | E17: 11/28/1977 | F17: 05/06/2014 | H17: M02 | I17: 83000 | J17: Active | K17: Male | L17: Kolkata
A18: EMP4164 | B18: Shreya Bhatia | C18: Marketing | D18: 12-05-2011 | E18: 13/09/1969 | F18: 01 Jun 2016 | G18: 2 | H18: M05 | I18: 57000 | J18: active | K18: Female | L18: Mumbai
A19: EMP4114 | B19: Nikhil Singh | C19: IT | D19: 26-09-2010 | E19: 1971-11-24 | F19: 14/06/2012 | G19: 2 | H19: M06 | I19: 114000 | J19: Active | K19: Female | L19: Pune
A20: EMP7211 | B20: Geeta Trivedi | C20: HR | D20: 10/10/2019 | E20: 27/09/1985 | F20: 10 May 2020 | G20: 3 | H20: M06 | I20: 94000 | J20: ACTIVE | K20: Female | L20: Chennai
A21: EMP6491 | B21: Ananya Desai | D21: 08/05/2020 | E21: 03/01/1992 | F21: 16 Apr 2021 | G21: 4 | H21: M02 | I21: 93000 | J21: Active | K21: Female | L21: Pune
A22: EMP2746 | B22: Hema Rao | C22: Finance | D22: 17 Dec 2012 | E22: 18/01/1976 | F22: 15/02/2014 | G22: 2 | H22: M08 | I22: 120000 | J22: ACTIVE | K22: Female | L22: Kolkata
A23: EMP5050 | B23: Naveen Chauhan | C23: Legal | D23: 09 Apr 2020 | E23: 02/23/1984 | F23: 04/09/2023 | G23: 3 | H23: M02 | I23: Rs.52000 | J23: Active | K23: Male | L23: Delhi
A24: EMP1320 | B24: Kapil Bose | C24: IT | D24: 12 Jan 2017 | E24: 28 Jul 1986 | F24: 24-09-2021 | G24: 4 | H24: M04 | I24: 97000 | J24: active | K24: M | L24: Bangalore
A25: EMP9751 | B25: Priya Iyer | C25: Sales | D25: 14 Nov 2011 | E25: 1985-08-06 | F25: 13 May 2012 | G25: 3 | H25: M08 | I25: 76000 | J25: Active | K25: Female | L25: Kolkata
A26: EMP2124 | B26: Hema Sinha | C26: Sales | D26: 2022-01-08 | E26: 1994-01-20 | F26: 04/05/2023 | G26: 3 | H26: M02 | I26: 107000 | J26: ACTIVE | K26: Male | L26: Chennai
A27: EMP1420 | B27: Ritu Bose | C27: IT | D27: 07/12/2016 | E27: 23 Oct 1992 | F27: 2018-02-23 | G27: 4 | H27: M02 | I27: Rs.136000 | J27: active | K27: Male | L27: Bangalore
A28: EMP6934 | B28: Naveen Krishnan | C28: HR | D28: 03/24/2016 | E28: 09-11-1978 | F28: 2021-09-25 | H28: M07 | I28: 140000 | J28: Active | K28: Female | L28: Bangalore
A29: EMP6325 | B29: Divya Choudhury | C29: Finance | D29: 11 May 2015 | E29: 23 Oct 1985 | F29: 01/09/2018 | G29: 4 | H29: M04 | I29: 45000 | J29: active | K29: Male | L29: Pune
A30: EMP4630 | B30: Shreya Rathore | C30: Finance | D30: 2014-11-19 | E30: 1981-08-18 | F30: 06/14/2019 | G30: 5 | H30: M06 | I30: 80000 | J30: Active | K30: Female | L30: Bangalore
A31: EMP4545 | B31: Radha Subramaniam | C31: Marketing | D31: 25/10/2021 | E31: 10/10/1983 | F31: 2022-04-10 | G31: 3 | H31: M03 | I31: Rs.73000 | J31: Active | K31: Male | L31: Pune
A32: EMP2680 | B32: Aarav Bose | C32: Marketing | D32: 15-08-2017 | E32: 03/02/1985 | F32: 08/04/2020 | G32: 4 | H32: M07 | I32: 97000 | J32: ACTIVE | K32: Male | L32: Hyderabad
A33: EMP4697 | B33: Hema Dutta | D33: 08/10/2017 | E33: 1977-07-10 | F33: 02-10-2022 | G33: 4 | H33: M02 | I33: 132000 | J33: Active | K33: Male | L33: Pune
A34: EMP5771 | B34: Rohit Saxena | C34: Marketing | D34: 05/23/2021 | E34: 02/22/1985 | F34: 2023-05-26 | G34: 4 | H34: M04 | I34: 89000 | J34: Active | K34: Male | L34: Hyderabad
A35: EMP5728 | B35: Alok Yadav | C35: Legal | D35: 2021-05-23 | E35: 17/05/1987 | F35: 2023-08-15 | H35: M01 | I35: Rs.148000 | J35: Active | K35: Female | L35: Pune
A36: EMP5415 | B36: Pranav Singh | C36: HR | D36: 2017-09-21 | E36: 1981-05-06 | F36: 21-07-2022 | G36: 4 | H36: M02 | I36: 95000 | J36: Active | K36: Female | L36: Chennai
A37: EMP1601 | B37: Bhavna Joshi | C37: Operations | D37: 2014-06-04 | E37: 27/09/1980 | F37: 28 Nov 2015 | G37: 4 | H37: M07 | I37: 41000 | J37: active | K37: Male | L37: Hyderabad
A38: EMP8941 | B38: Meera Verma | C38: Finance | D38: 03/10/2021 | E38: 18 Jan 1982 | F38: 2023-02-08 | G38: 5 | H38: M02 | I38: 94000 | J38: Active | K38: M | L38: Pune
A39: EMP7284 | B39: Amit Chakraborty | C39: HR | D39: 05/25/2011 | E39: 26 Jun 1976 | F39: 27/05/2016 | G39: 1 | H39: M05 | I39: 142000 | J39: Active | K39: F | L39: Kolkata
A40: EMP4912 | B40: Pranav Nair | C40: Finance | D40: 02/07/2022 | E40: 16/12/1990 | F40: 2023-07-22 | G40: 4 | H40: M03 | I40: 98000 | J40: ACTIVE | K40: Male | L40: Delhi
...

Sheet Lookup_Tables
A1: Manager Lookup | D1: Department Budget Lookup
A2: Manager ID | B2: Manager Name | D2: Department | E2: Annual Budget (₹)
A3: M01 | B3: Rajiv Khanna | D3: Sales | E3: 12000000
A4: M02 | B4: Sunita Bose | D4: Engineering | E4: 18000000
A5: M03 | B5: Anil Desai | D5: HR | E5: 4500000
A6: M04 | B6: Preethi Nair | D6: Finance | E6: 6000000
A7: M05 | B7: Siddharth Roy | D7: Marketing | E7: 8000000
A8: M06 | B8: Geeta Pillai | D8: Operations | E8: 9500000
A9: M07 | B9: Manish Tiwari | D9: IT | E9: 11000000
A10: M08 | B10: Divya Reddy | D10: Legal | E10: 3500000

Sheet Clean_Data
A1: EmpID | B1: Full Name | C1: Department | D1: Hire Date | E1: DOB | F1: Last Promotion Date | G1: Performance Rating (1-5) | H1: Manager ID | I1: Monthly Salary | J1: Status | K1: Gender | L1: City | M1: Manager Name | N1: Dept Formula
A2: EMP2824 | B2: Priya Trivedi | C2: Marketing | D2: 41398 | E2: 24890 | F2: 43150 | G2: 3 | H2: M01 | I2: 46000 | J2: Active | K2: Male | L2: Delhi | M2: =_xlfn.XLOOKUP(Clean_Data[[#This Row],[Manager ID]],Lookup_Tables!$A$3:$A$10,Lookup_Tables!$B$3:$B$10) -> Rajiv Khanna | N2: =_xlfn.XLOOKUP(Clean_Data[[#This Row],[Department]],Lookup_Tables!$D$3:$D$10,Lookup_Tables!$E$3:$E$10) -> 8000000
A3: EMP1106 | B3: Kapil Pandey | C3: IT | D3: 42129 | E3: 31932 | F3: 42467 | G3: 3 | H3: M06 | I3: 112000 | J3: Active | K3: Female | L3: Kolkata | M3: =_xlfn.XLOOKUP(Clean_Data[[#This Row],[Manager ID]],Lookup_Tables!$A$3:$A$10,Lookup_Tables!$B$3:$B$10) -> Geeta Pillai | N3: =_xlfn.XLOOKUP(Clean_Data[[#This Row],[Department]],Lookup_Tables!$D$3:$D$10,Lookup_Tables!$E$3:$E$10) -> 11000000
A4: EMP6925 | B4: Pranav Agarwal | C4: Engineering | D4: 40490 | E4: 28914 | F4: 40952 | G4: 3 | H4: M06 | I4: 55000 | J4: Active | K4: Female | L4: Bangalore | M4: =_xlfn.XLOOKUP(Clean_Data[[#This Row],[Manager ID]],Lookup_Tables!$A$3:$A$10,Lookup_Tables!$B$3:$B$10) -> Geeta Pillai | N4: =_xlfn.XLOOKUP(Clean_Data[[#This Row],[Department]],Lookup_Tables!$D$3:$D$10,Lookup_Tables!$E$3:$E$10) -> 18000000
A5: EMP4598 | B5: Geeta Goel | C5: Sales | D5: 41300 | E5: 29776 | F5: 41748 | G5: 5 | H5: M06 | I5: 62000 | J5: Active | K5: Female | L5: Chennai | M5: =_xlfn.XLOOKUP(Clean_Data[[#This Row],[Manager ID]],Lookup_Tables!$A$3:$A$10,Lookup_Tables!$B$3:$B$10) -> Geeta Pillai | N5: =_xlfn.XLOOKUP(Clean_Data[[#This Row],[Department]],Lookup_Tables!$D$3:$D$10,Lookup_Tables!$E$3:$E$10) -> 12000000
A6: EMP6930 | B6: Suresh Mishra | C6: Legal | D6: 40571 | E6: 31492 | F6: 41592 | G6: 4 | H6: M07 | I6: 83000 | J6: Active | K6: Female | L6: Hyderabad | M6: =_xlfn.XLOOKUP(Clean_Data[[#This Row],[Manager ID]],Lookup_Tables!$A$3:$A$10,Lookup_Tables!$B$3:$B$10) -> Manish Tiwari | N6: =_xlfn.XLOOKUP(Clean_Data[[#This Row],[Department]],Lookup_Tables!$D$3:$D$10,Lookup_Tables!$E$3:$E$10) -> 3500000
A7: EMP5808 | B7: Neha Pandey | C7: Legal | D7: 40536 | E7: 29489 | F7: 41008 | G7: 5 | H7: M05 | I7: 142000 | J7: Active | K7: Male | L7: Delhi | M7: =_xlfn.XLOOKUP(Clean_Data[[#This Row],[Manager ID]],Lookup_Tables!$A$3:$A$10,Lookup_Tables!$B$3:$B$10) -> Siddharth Roy | N7: =_xlfn.XLOOKUP(Clean_Data[[#This Row],[Department]],Lookup_Tables!$D$3:$D$10,Lookup_Tables!$E$3:$E$10) -> 3500000
A8: EMP6947 | B8: Ritu Srivastava | C8: Sales | D8: 41343 | E8: 32858 | F8: 41907 | G8: 2 | H8: M08 | I8: 105000 | J8: Active | K8: Male | L8: Bangalore | M8: =_xlfn.XLOOKUP(Clean_Data[[#This Row],[Manager ID]],Lookup_Tables!$A$3:$A$10,Lookup_Tables!$B$3:$B$10) -> Divya Reddy | N8: =_xlfn.XLOOKUP(Clean_Data[[#This Row],[Department]],Lookup_Tables!$D$3:$D$10,Lookup_Tables!$E$3:$E$10) -> 12000000
A9: EMP7118 | B9: Alok Dutta | C9: Legal | D9: 40759 | E9: 31783 | F9: 42621 | G9: 4 | H9: M01 | I9: 44000 | J9: Active | K9: Male | L9: Delhi | M9: =_xlfn.XLOOKUP(Clean_Data[[#This Row],[Manager ID]],Lookup_Tables!$A$3:$A$10,Lookup_Tables!$B$3:$B$10) -> Rajiv Khanna | N9: =_xlfn.XLOOKUP(Clean_Data[[#This Row],[Department]],Lookup_Tables!$D$3:$D$10,Lookup_Tables!$E$3:$E$10) -> 3500000
A10: EMP8744 | B10: Kavya Subramaniam | C10: IT | D10: 41309 | E10: 25761 | F10: 42931 | G10: 5 | H10: M01 | I10: 121000 | J10: Active | K10: Male | L10: Mumbai | M10: =_xlfn.XLOOKUP(Clean_Data[[#This Row],[Manager ID]],Lookup_Tables!$A$3:$A$10,Lookup_Tables!$B$3:$B$10) -> Rajiv Khanna | N10: =_xlfn.XLOOKUP(Clean_Data[[#This Row],[Department]],Lookup_Tables!$D$3:$D$10,Lookup_Tables!$E$3:$E$10) -> 11000000
A11: EMP2235 | B11: Alok Ghosh | C11: Engineering | D11: 40500 | E11: 32198 | F11: 40982 | G11: 3 | H11: M04 | I11: 145000 | J11: Active | K11: Female | L11: Mumbai | M11: =_xlfn.XLOOKUP(Clean_Data[[#This Row],[Manager ID]],Lookup_Tables!$A$3:$A$10,Lookup_Tables!$B$3:$B$10) -> Preethi Nair | N11: =_xlfn.XLOOKUP(Clean_Data[[#This Row],[Department]],Lookup_Tables!$D$3:$D$10,Lookup_Tables!$E$3:$E$10) -> 18000000
A12: EMP8973 | B12: Pooja Agarwal | C12: Marketing | D12: 41293 | E12: 24877 | F12: 42401 | G12: 4 | H12: M03 | I12: 42000 | J12: Active | K12: Male | L12: Kolkata | M12: =_xlfn.XLOOKUP(Clean_Data[[#This Row],[Manager ID]],Lookup_Tables!$A$3:$A$10,Lookup_Tables!$B$3:$B$10) -> Anil Desai | N12: =_xlfn.XLOOKUP(Clean_Data[[#This Row],[Department]],Lookup_Tables!$D$3:$D$10,Lookup_Tables!$E$3:$E$10) -> 8000000
A13: EMP1651 | B13: Usha Joshi | C13: IT | D13: 44123 | E13: 30111 | F13: 44888 | G13: 3 | H13: M05 | I13: 85000 | J13: Active | K13: Male | L13: Pune | M13: =_xlfn.XLOOKUP(Clean_Data[[#This Row],[Manager ID]],Lookup_Tables!$A$3:$A$10,Lookup_Tables!$B$3:$B$10) -> Siddharth Roy | N13: =_xlfn.XLOOKUP(Clean_Data[[#This Row],[Department]],Lookup_Tables!$D$3:$D$10,Lookup_Tables!$E$3:$E$10) -> 11000000
... A51: EMP9543 | B51: Ritu Krishnan | C51: Sales | D51: 40418 | E51: 27963 | F51: 40778 | G51: 5 | H51: M02 | I51: 150000 | J51: Active | K51: Male | L51: Bangalore | M51: =_xlfn.XLOOKUP(Clean_Data[[#This Row],[Manager ID]],Lookup_Tables!$A$3:$A$10,Lookup_Tables!$B$3:$B$10) -> Sunita Bose | N51: =_xlfn.XLOOKUP(Clean_Data[[#This Row],[Department]],Lookup_Tables!$D$3:$D$10,Lookup_Tables!$E$3:$E$10) -> 12000000

Sheet Pivot
A2: Row Labels | B2: Average of Risk Score
A3: Anil Desai | B3: 56.625
A4: Divya Reddy | B4: 62.025
A5: Geeta Pillai | B5: 57.014286
A6: Manish Tiwari | B6: 56.85
A7: Preethi Nair | B7: 53.52
A8: Rajiv Khanna | B8: 48.22
A9: Siddharth Roy | B9: 56.557143
A10: Sunita Bose | B10: 52.37
A11: Grand Total | B11: 55.136
A13: Row Labels | B13: Average of Risk Score
A14: Engineering | B14: 58.525
A15: Finance | B15: 55.242857
A16: HR | B16: 60.316667
A17: IT | B17: 56.283333
A18: Legal | B18: 47.6
A19: Marketing | B19: 57.477778
A20: Sales | B20: 54
A21: Operations | B21: 48.775
A22: Grand Total | B22: 55.136
A24: Row Labels | B24: Max of Risk Score
A25: Aarav Bose | B25: 62.6
A26: Amit Chakraborty | B26: 65
A27: Ananya Desai | B27: 69.6
A28: Geeta Trivedi | B28: 73.5
A29: Hema Rao | B29: 63.4
A30: Kapil Bhattacharya | B30: 66.5
A31: Lata Tiwari | B31: 62.6
A32: Radha Subramaniam | B32: 70.2
A33: Ritu Srivastava | B33: 63.4
A34: Tarun Sen | B34: 66.5
A35: Vinod Patel | B35: 67.8
A36: Grand Total | B36: 73.5
A39: Row Labels | B39: Count of Emp ID
A40: High Risk | B40: 2
A41: Low Risk | B41: 6
A42: Medium Risk | B42: 42
A43: Grand Total | B43: 50

Sheet Risk_Score
A1: Adjustable Weights (Yellow Cells are editable)
A2: Weight - Tenure (W1) | B2: 0.35 | C2: ← Longer Gaps = High Risk
A3: Weight - Promo Gap (W2) | B3: 0.4 | C3: ← Longer Since Last Promotion = High Risk
A4: Weight - Performance (W3) | B4: 0.25 | C4: ← Lower rating = High Risk
A5: ⚠️ W1+W2+W3 must = 100% | B5: 1
A7: Emp ID | B7: Name | C7: Department | D7: Manager Name | E7: Tenure Yrs | F7: Age | G7: Age Band | H7: Promo Gap Yrs | I7: Perf Rating | J7: Tenure Score | K7: Promo Gap Score | L7: Perf Score | M7: Risk Score | N7: Risk Band | O7: Rank
A8: =Clean_Data!A2 -> EMP2824 | B8: =Clean_Data!B2 -> Priya Trivedi | C8: =Clean_Data!C2 -> Marketing | D8: =Clean_Data!M2 -> Rajiv Khanna | E8: =DATEDIF(INDEX(Clean_Data[Hire Date],MATCH(Risk_Score!B8,Clean_Data[Full Name],0)),TODAY(),"Y") -> 13 | F8: =DATEDIF(Clean_Data!E2, TODAY(), "Y") -> 58 | G8: =IF(F8 < 30, "Under 30", IF(F8< 40, "30-39", IF(F8< 50, "40-49", "50+") ) ) -> 50+ | H8: =DATEDIF(Clean_Data!F2,TODAY(), "Y") -> 8 | I8: =Clean_Data!G2 -> 3 | J8: =MAX(0,(MIN(100,(15-E8)/15*100))) -> 13.333333 | K8: =MIN(100, H8/5*100) -> 100 | L8: =(5-I8)/4*100 -> 50 | M8: =ROUND($B$2 *J8 + $B$3 *K8 + $B$4 *L8, 1) -> 57.2 | N8: =IF(M8 >=70, "High Risk", IF(M8 >= 45, "Medium Risk", "Low Risk")) -> Medium Risk | O8: =RANK(M8, $M$8:$M$57, 0) + COUNTIF($M$8:M8, M8) - 1 -> 22
A9: =Clean_Data!A3 -> EMP1106 | B9: =Clean_Data!B3 -> Kapil Pandey | C9: =Clean_Data!C3 -> IT | D9: =Clean_Data!M3 -> Geeta Pillai | E9: =DATEDIF(INDEX(Clean_Data[Hire Date],MATCH(Risk_Score!B9,Clean_Data[Full Name],0)),TODAY(),"Y") -> 11 | F9: =DATEDIF(Clean_Data!E3, TODAY(), "Y") -> 38 | G9: =IF(F9 < 30, "Under 30", IF(F9< 40, "30-39", IF(F9< 50, "40-49", "50+") ) ) -> 30-39 | H9: =DATEDIF(Clean_Data!F3,TODAY(), "Y") -> 10 | I9: =Clean_Data!G3 -> 3 | J9: =MAX(0,(MIN(100,(15-E9)/15*100))) -> 26.666667 | K9: =MIN(100, H9/5*100) -> 100 | L9: =(5-I9)/4*100 -> 50 | M9: =ROUND($B$2 *J9 + $B$3 *K9 + $B$4 *L9, 1) -> 61.8 | N9: =IF(M9 >=70, "High Risk", IF(M9 >= 45, "Medium Risk", "Low Risk")) -> Medium Risk | O9: =RANK(M9, $M$8:$M$57, 0) + COUNTIF($M$8:M9, M9) - 1 -> 13
A10: =Clean_Data!A4 -> EMP6925 | B10: =Clean_Data!B4 -> Pranav Agarwal | C10: =Clean_Data!C4 -> Engineering | D10: =Clean_Data!M4 -> Geeta Pillai | E10: =DATEDIF(INDEX(Clean_Data[Hire Date],MATCH(Risk_Score!B10,Clean_Data[Full Name],0)),TODAY(),"Y") -> 15 | F10: =DATEDIF(Clean_Data!E4, TODAY(), "Y") -> 47 | G10: =IF(F10 < 30, "Under 30", IF(F10< 40, "30-39", IF(F10< 50, "40-49", "50+") ) ) -> 40-49 | H10: =DATEDIF(Clean_Data!F4,TODAY(), "Y") -> 14 | I10: =Clean_Data!G4 -> 3 | J10: =MAX(0,(MIN(100,(15-E10)/15*100))) -> 0 | K10: =MIN(100, H10/5*100) -> 100 | L10: =(5-I10)/4*100 -> 50 | M10: =ROUND($B$2 *J10 + $B$3 *K10 + $B$4 *L10, 1) -> 52.5 | N10: =IF(M10 >=70, "High Risk", IF(M10 >= 45, "Medium Risk", "Low Risk")) -> Medium Risk | O10: =RANK(M10, $M$8:$M$57, 0) + COUNTIF($M$8:M10, M10) - 1 -> 30
A11: =Clean_Data!A5 -> EMP4598 | B11: =Clean_Data!B5 -> Geeta Goel | C11: =Clean_Data!C5 -> Sales | D11: =Clean_Data!M5 -> Geeta Pillai | E11: =DATEDIF(INDEX(Clean_Data[Hire Date],MATCH(Risk_Score!B11,Clean_Data[Full Name],0)),TODAY(),"Y") -> 13 | F11: =DATEDIF(Clean_Data!E5, TODAY(), "Y") -> 44 | G11: =IF(F11 < 30, "Under 30", IF(F11< 40, "30-39", IF(F11< 50, "40-49", "50+") ) ) -> 40-49 | H11: =DATEDIF(Clean_Data!F5,TODAY(), "Y") -> 12 | I11: =Clean_Data!G5 -> 5 | J11: =MAX(0,(MIN(100,(15-E11)/15*100))) -> 13.333333 | K11: =MIN(100, H11/5*100) -> 100 | L11: =(5-I11)/4*100 -> 0 | M11: =ROUND($B$2 *J11 + $B$3 *K11 + $B$4 *L11, 1) -> 44.7 | N11: =IF(M11 >=70, "High Risk", IF(M11 >= 45, "Medium Risk", "Low Risk")) -> Low Risk | O11: =RANK(M11, $M$8:$M$57, 0) + COUNTIF($M$8:M11, M11) - 1 -> 45
A12: =Clean_Data!A6 -> EMP6930 | B12: =Clean_Data!B6 -> Suresh Mishra | C12: =Clean_Data!C6 -> Legal | D12: =Clean_Data!M6 -> Manish Tiwari | E12: =DATEDIF(INDEX(Clean_Data[Hire Date],MATCH(Risk_Score!B12,Clean_Data[Full Name],0)),TODAY(),"Y") -> 15 | F12: =DATEDIF(Clean_Data!E6, TODAY(), "Y") -> 40 | G12: =IF(F12 < 30, "Under 30", IF(F12< 40, "30-39", IF(F12< 50, "40-49", "50+") ) ) -> 40-49 | H12: =DATEDIF(Clean_Data!F6,TODAY(), "Y") -> 12 | I12: =Clean_Data!G6 -> 4 | J12: =MAX(0,(MIN(100,(15-E12)/15*100))) -> 0 | K12: =MIN(100, H12/5*100) -> 100 | L12: =(5-I12)/4*100 -> 25 | M12: =ROUND($B$2 *J12 + $B$3 *K12 + $B$4 *L12, 1) -> 46.3 | N12: =IF(M12 >=70, "High Risk", IF(M12 >= 45, "Medium Risk", "Low Risk")) -> Medium Risk | O12: =RANK(M12, $M$8:$M$57, 0) + COUNTIF($M$8:M12, M12) - 1 -> 42
A13: =Clean_Data!A7 -> EMP5808 | B13: =Clean_Data!B7 -> Neha Pandey | C13: =Clean_Data!C7 -> Legal | D13: =Clean_Data!M7 -> Siddharth Roy | E13: =DATEDIF(INDEX(Clean_Data[Hire Date],MATCH(Risk_Score!B13,Clean_Data[Full Name],0)),TODAY(),"Y") -> 15 | F13: =DATEDIF(Clean_Data!E7, TODAY(), "Y") -> 45 | G13: =IF(F13 < 30, "Under 30", IF(F13< 40, "30-39", IF(F13< 50, "40-49", "50+") ) ) -> 40-49 | H13: =DATEDIF(Clean_Data!F7,TODAY(), "Y") -> 14 | I13: =Clean_Data!G7 -> 5 | J13: =MAX(0,(MIN(100,(15-E13)/15*100))) -> 0 | K13: =MIN(100, H13/5*100) -> 100 | L13: =(5-I13)/4*100 -> 0 | M13: =ROUND($B$2 *J13 + $B$3 *K13 + $B$4 *L13, 1) -> 40 | N13: =IF(M13 >=70, "High Risk", IF(M13 >= 45, "Medium Risk", "Low Risk")) -> Low Risk | O13: =RANK(M13, $M$8:$M$57, 0) + COUNTIF($M$8:M13, M13) - 1 -> 49
A14: =Clean_Data!A8 -> EMP6947 | B14: =Clean_Data!B8 -> Ritu Srivastava | C14: =Clean_Data!C8 -> Sales | D14: =Clean_Data!M8 -> Divya Reddy | E14: =DATEDIF(INDEX(Clean_Data[Hire Date],MATCH(Risk_Score!B14,Clean_Data[Full Name],0)),TODAY(),"Y") -> 13 | F14: =DATEDIF(Clean_Data!E8, TODAY(), "Y") -> 36 | G14: =IF(F14 < 30, "Under 30", IF(F14< 40, "30-39", IF(F14< 50, "40-49", "50+") ) ) -> 30-39 | H14: =DATEDIF(Clean_Data!F8,TODAY(), "Y") -> 11 | I14: =Clean_Data!G8 -> 2 | J14: =MAX(0,(MIN(100,(15-E14)/15*100))) -> 13.333333 | K14: =MIN(100, H14/5*100) -> 100 | L14: =(5-I14)/4*100 -> 75 | M14: =ROUND($B$2 *J14 + $B$3 *K14 + $B$4 *L14, 1) -> 63.4 | N14: =IF(M14 >=70, "High Risk", IF(M14 >= 45, "Medium Risk", "Low Risk")) -> Medium Risk | O14: =RANK(M14, $M$8:$M$57, 0) + COUNTIF($M$8:M14, M14) - 1 -> 8
A15: =Clean_Data!A9 -> EMP7118 | B15: =Clean_Data!B9 -> Alok Dutta | C15: =Clean_Data!C9 -> Legal | D15: =Clean_Data!M9 -> Rajiv Khanna | E15: =DATEDIF(INDEX(Clean_Data[Hire Date],MATCH(Risk_Score!B15,Clean_Data[Full Name],0)),TODAY(),"Y") -> 14 | F15: =DATEDIF(Clean_Data!E9, TODAY(), "Y") -> 39 | G15: =IF(F15 < 30, "Under 30", IF(F15< 40, "30-39", IF(F15< 50, "40-49", "50+") ) ) -> 30-39 | H15: =DATEDIF(Clean_Data!F9,TODAY(), "Y") -> 9 | I15: =Clean_Data!G9 -> 4 | J15: =MAX(0,(MIN(100,(15-E15)/15*100))) -> 6.6666667 | K15: =MIN(100, H15/5*100) -> 100 | L15: =(5-I15)/4*100 -> 25 | M15: =ROUND($B$2 *J15 + $B$3 *K15 + $B$4 *L15, 1) -> 48.6 | N15: =IF(M15 >=70, "High Risk", IF(M15 >= 45, "Medium Risk", "Low Risk")) -> Medium Risk | O15: =RANK(M15, $M$8:$M$57, 0) + COUNTIF($M$8:M15, M15) - 1 -> 37
A16: =Clean_Data!A10 -> EMP8744 | B16: =Clean_Data!B10 -> Kavya Subramaniam | C16: =Clean_Data!C10 -> IT | D16: =Clean_Data!M10 -> Rajiv Khanna | E16: =DATEDIF(INDEX(Clean_Data[Hire Date],MATCH(Risk_Score!B16,Clean_Data[Full Name],0)),TODAY(),"Y") -> 13 | F16: =DATEDIF(Clean_Data!E10, TODAY(), "Y") -> 55 | G16: =IF(F16 < 30, "Under 30", IF(F16< 40, "30-39", IF(F16< 50, "40-49", "50+") ) ) -> 50+ | H16: =DATEDIF(Clean_Data!F10,TODAY(), "Y") -> 8 | I16: =Clean_Data!G10 -> 5 | J16: =MAX(0,(MIN(100,(15-E16)/15*100))) -> 13.333333 | K16: =MIN(100, H16/5*100) -> 100 | L16: =(5-I16)/4*100 -> 0 | M16: =ROUND($B$2 *J16 + $B$3 *K16 + $B$4 *L16, 1) -> 44.7 | N16: =IF(M16 >=70, "High Risk", IF(M16 >= 45, "Medium Risk", "Low Risk")) -> Low Risk | O16: =RANK(M16, $M$8:$M$57, 0) + COUNTIF($M$8:M16, M16) - 1 -> 46
A17: =Clean_Data!A11 -> EMP2235 | B17: =Clean_Data!B11 -> Alok Ghosh | C17: =Clean_Data!C11 -> Engineering | D17: =Clean_Data!M11 -> Preethi Nair | E17: =DATEDIF(INDEX(Clean_Data[Hire Date],MATCH(Risk_Score!B17,Clean_Data[Full Name],0)),TODAY(),"Y") -> 15 | F17: =DATEDIF(Clean_Data!E11, TODAY(), "Y") -> 38 | G17: =IF(F17 < 30, "Under 30", IF(F17< 40, "30-39", IF(F17< 50, "40-49", "50+") ) ) -> 30-39 | H17: =DATEDIF(Clean_Data!F11,TODAY(), "Y") -> 14 | I17: =Clean_Data!G11 -> 3 | J17: =MAX(0,(MIN(100,(15-E17)/15*100))) -> 0 | K17: =MIN(100, H17/5*100) -> 100 | L17: =(5-I17)/4*100 -> 50 | M17: =ROUND($B$2 *J17 + $B$3 *K17 + $B$4 *L17, 1) -> 52.5 | N17: =IF(M17 >=70, "High Risk", IF(M17 >= 45, "Medium Risk", "Low Risk")) -> Medium Risk | O17: =RANK(M17, $M$8:$M$57, 0) + COUNTIF($M$8:M17, M17) - 1 -> 31
A18: =Clean_Data!A12 -> EMP8973 | B18: =Clean_Data!B12 -> Pooja Agarwal | C18: =Clean_Data!C12 -> Marketing | D18: =Clean_Data!M12 -> Anil Desai | E18: =DATEDIF(INDEX(Clean_Data[Hire Date],MATCH(Risk_Score!B18,Clean_Data[Full Name],0)),TODAY(),"Y") -> 13 | F18: =DATEDIF(Clean_Data!E12, TODAY(), "Y") -> 58 | G18: =IF(F18 < 30, "Under 30", IF(F18< 40, "30-39", IF(F18< 50, "40-49", "50+") ) ) -> 50+ | H18: =DATEDIF(Clean_Data!F12,TODAY(), "Y") -> 10 | I18: =Clean_Data!G12 -> 4 | J18: =MAX(0,(MIN(100,(15-E18)/15*100))) -> 13.333333 | K18: =MIN(100, H18/5*100) -> 100 | L18: =(5-I18)/4*100 -> 25 | M18: =ROUND($B$2 *J18 + $B$3 *K18 + $B$4 *L18, 1) -> 50.9 | N18: =IF(M18 >=70, "High Risk", IF(M18 >= 45, "Medium Risk", "Low Risk")) -> Medium Risk | O18: =RANK(M18, $M$8:$M$57, 0) + COUNTIF($M$8:M18, M18) - 1 -> 33
A19: =Clean_Data!A13 -> EMP1651 | B19: =Clean_Data!B13 -> Usha Joshi | C19: =Clean_Data!C13 -> IT | D19: =Clean_Data!M13 -> Siddharth Roy | E19: =DATEDIF(INDEX(Clean_Data[Hire Date],MATCH(Risk_Score!B19,Clean_Data[Full Name],0)),TODAY(),"Y") -> 5 | F19: =DATEDIF(Clean_Data!E13, TODAY(), "Y") -> 43 | G19: =IF(F19 < 30, "Under 30", IF(F19< 40, "30-39", IF(F19< 50, "40-49", "50+") ) ) -> 40-49 | H19: =DATEDIF(Clean_Data!F13,TODAY(), "Y") -> 3 | I19: =Clean_Data!G13 -> 3 | J19: =MAX(0,(MIN(100,(15-E19)/15*100))) -> 66.666667 | K19: =MIN(100, H19/5*100) -> 60 | L19: =(5-I19)/4*100 -> 50 | M19: =ROUND($B$2 *J19 + $B$3 *K19 + $B$4 *L19, 1) -> 59.8 | N19: =IF(M19 >=70, "High Risk", IF(M19 >= 45, "Medium Risk", "Low Risk")) -> Medium Risk | O19: =RANK(M19, $M$8:$M$57, 0) + COUNTIF($M$8:M19, M19) - 1 -> 17
... A57: =Clean_Data!A51 -> EMP9543 | B57: =Clean_Data!B51 -> Ritu Krishnan | C57: =Clean_Data!C51 -> Sales | D57: =Clean_Data!M51 -> Sunita Bose | E57: =DATEDIF(INDEX(Clean_Data[Hire Date],MATCH(Risk_Score!B57,Clean_Data[Full Name],0)),TODAY(),"Y") -> 15 | F57: =DATEDIF(Clean_Data!E51, TODAY(), "Y") -> 49 | G57: =IF(F57 < 30, "Under 30", IF(F57< 40, "30-39", IF(F57< 50, "40-49", "50+") ) ) -> 40-49 | H57: =DATEDIF(Clean_Data!F51,TODAY(), "Y") -> 14 | I57: =Clean_Data!G51 -> 5 | J57: =MAX(0,(MIN(100,(15-E57)/15*100))) -> 0 | K57: =MIN(100, H57/5*100) -> 100 | L57: =(5-I57)/4*100 -> 0 | M57: =ROUND($B$2 *J57 + $B$3 *K57 + $B$4 *L57, 1) -> 40 | N57: =IF(M57 >=70, "High Risk", IF(M57 >= 45, "Medium Risk", "Low Risk")) -> Low Risk | O57: =RANK(M57, $M$8:$M$57, 0) + COUNTIF($M$8:M57, M57) - 1 -> 50

Sheet Dashboard
A1: HR Attrition Risk Dashboard | Top 20 At-Risk Employees
B4: Total Employee | E4: High Risk >=70 | H4: Medium Risk 45 - 69 | K4: Low Risk (>45) | N4: Avg Risk Score
B5: =COUNTA(Risk_Score!A8:A57) -> 50 | E5: =COUNTIF(Risk_Score!N8:N57, "High Risk") -> 2 | H5: =COUNTIF(Risk_Score!N8:N57, "Medium Risk") -> 42 | K5: =COUNTIF(Risk_Score!N8:N57, "Low Risk") -> 6 | N5: =AVERAGE(Risk_Score!M8:M57) -> 55.136
A7: Rank | B7: Employee ID | C7: Employee Name | D7: Manager | E7: Department | F7: Tenure Year | G7: Age Band | H7: Promo Gap Yrs | I7: Performance | J7: Tenure Score | K7: Promo Gap Score | L7: Perf Score | M7: Risk Score | N7: Risk Band
A8: 1 | B8: =INDEX(Risk_Score!$A$8:$A$57, MATCH(1, Risk_Score!$O$8:$O$57, 0)) -> EMP7211 | C8: =INDEX(Risk_Score!$B$8:$B$57, MATCH(1, Risk_Score!$O$8:$O$57, 0)) -> Geeta Trivedi | D8: =INDEX(Risk_Score!$D$8:$D$57, MATCH(1, Risk_Score!$O$8:$O$57, 0)) -> Geeta Pillai | E8: =INDEX(Risk_Score!$C$8:$C$57, MATCH(1, Risk_Score!$O$8:$O$57, 0)) -> HR | F8: =INDEX(Risk_Score!$E$8:$E$57, MATCH(1, Risk_Score!$O$8:$O$57, 0)) -> 6 | G8: =INDEX(Risk_Score!$G$8:$G$57, MATCH(1, Risk_Score!$O$8:$O$57, 0)) -> 40-49 | H8: =INDEX(Risk_Score!$H$8:$H$57, MATCH(1, Risk_Score!$O$8:$O$57, 0)) -> 6 | I8: =INDEX(Risk_Score!$I$8:$I$57, MATCH(1, Risk_Score!$O$8:$O$57, 0)) -> 3 | J8: =INDEX(Risk_Score!$J$8:$J$57, MATCH(1, Risk_Score!$O$8:$O$57, 0)) -> 60 | K8: =INDEX(Risk_Score!$K$8:$K$57, MATCH(1, Risk_Score!$O$8:$O$57, 0)) -> 100 | L8: =INDEX(Risk_Score!$L$8:$L$57, MATCH(1, Risk_Score!$O$8:$O$57, 0)) -> 50 | M8: =INDEX(Risk_Score!$M$8:$M$57, MATCH(1, Risk_Score!$O$8:$O$57, 0)) -> 73.5 | N8: =INDEX(Risk_Score!$N$8:$N$57, MATCH(1, Risk_Score!$O$8:$O$57, 0)) -> High Risk
A9: 2 | B9: =INDEX(Risk_Score!$A$8:$A$57, MATCH(2, Risk_Score!$O$8:$O$57, 0)) -> EMP4545 | C9: =INDEX(Risk_Score!$B$8:$B$57, MATCH(2, Risk_Score!$O$8:$O$57, 0)) -> Radha Subramaniam | D9: =INDEX(Risk_Score!$D$8:$D$57, MATCH(2, Risk_Score!$O$8:$O$57, 0)) -> Anil Desai | E9: =INDEX(Risk_Score!$C$8:$C$57, MATCH(2, Risk_Score!$O$8:$O$57, 0)) -> Marketing | F9: =INDEX(Risk_Score!$E$8:$E$57, MATCH(2, Risk_Score!$O$8:$O$57, 0)) -> 4 | G9: =INDEX(Risk_Score!$G$8:$G$57, MATCH(2, Risk_Score!$O$8:$O$57, 0)) -> 40-49 | H9: =INDEX(Risk_Score!$H$8:$H$57, MATCH(2, Risk_Score!$O$8:$O$57, 0)) -> 4 | I9: =INDEX(Risk_Score!$I$8:$I$57, MATCH(2, Risk_Score!$O$8:$O$57, 0)) -> 3 | J9: =INDEX(Risk_Score!$J$8:$J$57, MATCH(2, Risk_Score!$O$8:$O$57, 0)) -> 73.333333 | K9: =INDEX(Risk_Score!$K$8:$K$57, MATCH(2, Risk_Score!$O$8:$O$57, 0)) -> 80 | L9: =INDEX(Risk_Score!$L$8:$L$57, MATCH(2, Risk_Score!$O$8:$O$57, 0)) -> 50 | M9: =INDEX(Risk_Score!$M$8:$M$57, MATCH(2, Risk_Score!$O$8:$O$57, 0)) -> 70.2 | N9: =INDEX(Risk_Score!$N$8:$N$57, MATCH(2, Risk_Score!$O$8:$O$57, 0)) -> High Risk
A10: 3 | B10: =INDEX(Risk_Score!$A$8:$A$57, MATCH(3, Risk_Score!$O$8:$O$57, 0)) -> EMP6491 | C10: =INDEX(Risk_Score!$B$8:$B$57, MATCH(3, Risk_Score!$O$8:$O$57, 0)) -> Ananya Desai | D10: =INDEX(Risk_Score!$D$8:$D$57, MATCH(3, Risk_Score!$O$8:$O$57, 0)) -> Sunita Bose | E10: =INDEX(Risk_Score!$C$8:$C$57, MATCH(3, Risk_Score!$O$8:$O$57, 0)) -> Finance | F10: =INDEX(Risk_Score!$E$8:$E$57, MATCH(3, Risk_Score!$O$8:$O$57, 0)) -> 5 | G10: =INDEX(Risk_Score!$G$8:$G$57, MATCH(3, Risk_Score!$O$8:$O$57, 0)) -> 30-39 | H10: =INDEX(Risk_Score!$H$8:$H$57, MATCH(3, Risk_Score!$O$8:$O$57, 0)) -> 5 | I10: =INDEX(Risk_Score!$I$8:$I$57, MATCH(3, Risk_Score!$O$8:$O$57, 0)) -> 4 | J10: =INDEX(Risk_Score!$J$8:$J$57, MATCH(3, Risk_Score!$O$8:$O$57, 0)) -> 66.666667 | K10: =INDEX(Risk_Score!$K$8:$K$57, MATCH(3, Risk_Score!$O$8:$O$57, 0)) -> 100 | L10: =INDEX(Risk_Score!$L$8:$L$57, MATCH(3, Risk_Score!$O$8:$O$57, 0)) -> 25 | M10: =INDEX(Risk_Score!$M$8:$M$57, MATCH(3, Risk_Score!$O$8:$O$57, 0)) -> 69.6 | N10: =INDEX(Risk_Score!$N$8:$N$57, MATCH(3, Risk_Score!$O$8:$O$57, 0)) -> Medium Risk
A11: 4 | B11: =INDEX(Risk_Score!$A$8:$A$57, MATCH(4, Risk_Score!$O$8:$O$57, 0)) -> EMP5847 | C11: =INDEX(Risk_Score!$B$8:$B$57, MATCH(4, Risk_Score!$O$8:$O$57, 0)) -> Vinod Patel | D11: =INDEX(Risk_Score!$D$8:$D$57, MATCH(4, Risk_Score!$O$8:$O$57, 0)) -> Siddharth Roy | E11: =INDEX(Risk_Score!$C$8:$C$57, MATCH(4, Risk_Score!$O$8:$O$57, 0)) -> Sales | F11: =INDEX(Risk_Score!$E$8:$E$57, MATCH(4, Risk_Score!$O$8:$O$57, 0)) -> 5 | G11: =INDEX(Risk_Score!$G$8:$G$57, MATCH(4, Risk_Score!$O$8:$O$57, 0)) -> Under 30 | H11: =INDEX(Risk_Score!$H$8:$H$57, MATCH(4, Risk_Score!$O$8:$O$57, 0)) -> 4 | I11: =INDEX(Risk_Score!$I$8:$I$57, MATCH(4, Risk_Score!$O$8:$O$57, 0)) -> 3 | J11: =INDEX(Risk_Score!$J$8:$J$57, MATCH(4, Risk_Score!$O$8:$O$57, 0)) -> 66.666667 | K11: =INDEX(Risk_Score!$K$8:$K$57, MATCH(4, Risk_Score!$O$8:$O$57, 0)) -> 80 | L11: =INDEX(Risk_Score!$L$8:$L$57, MATCH(4, Risk_Score!$O$8:$O$57, 0)) -> 50 | M11: =INDEX(Risk_Score!$M$8:$M$57, MATCH(4, Risk_Score!$O$8:$O$57, 0)) -> 67.8 | N11: =INDEX(Risk_Score!$N$8:$N$57, MATCH(4, Risk_Score!$O$8:$O$57, 0)) -> Medium Risk
A12: 5 | B12: =INDEX(Risk_Score!$A$8:$A$57, MATCH(5, Risk_Score!$O$8:$O$57, 0)) -> EMP2612 | C12: =INDEX(Risk_Score!$B$8:$B$57, MATCH(5, Risk_Score!$O$8:$O$57, 0)) -> Kapil Bhattacharya | D12: =INDEX(Risk_Score!$D$8:$D$57, MATCH(5, Risk_Score!$O$8:$O$57, 0)) -> Manish Tiwari | E12: =INDEX(Risk_Score!$C$8:$C$57, MATCH(5, Risk_Score!$O$8:$O$57, 0)) -> Engineering | F12: =INDEX(Risk_Score!$E$8:$E$57, MATCH(5, Risk_Score!$O$8:$O$57, 0)) -> 9 | G12: =INDEX(Risk_Score!$G$8:$G$57, MATCH(5, Risk_Score!$O$8:$O$57, 0)) -> 40-49 | H12: =INDEX(Risk_Score!$H$8:$H$57, MATCH(5, Risk_Score!$O$8:$O$57, 0)) -> 6 | I12: =INDEX(Risk_Score!$I$8:$I$57, MATCH(5, Risk_Score!$O$8:$O$57, 0)) -> 3 | J12: =INDEX(Risk_Score!$J$8:$J$57, MATCH(5, Risk_Score!$O$8:$O$57, 0)) -> 40 | K12: =INDEX(Risk_Score!$K$8:$K$57, MATCH(5, Risk_Score!$O$8:$O$57, 0)) -> 100 | L12: =INDEX(Risk_Score!$L$8:$L$57, MATCH(5, Risk_Score!$O$8:$O$57, 0)) -> 50 | M12: =INDEX(Risk_Score!$M$8:$M$57, MATCH(5, Risk_Score!$O$8:$O$57, 0)) -> 66.5 | N12: =INDEX(Risk_Score!$N$8:$N$57, MATCH(5, Risk_Score!$O$8:$O$57, 0)) -> Medium Risk
A13: 6 | B13: =INDEX(Risk_Score!$A$8:$A$57, MATCH(6, Risk_Score!$O$8:$O$57, 0)) -> EMP9850 | C13: =INDEX(Risk_Score!$B$8:$B$57, MATCH(6, Risk_Score!$O$8:$O$57, 0)) -> Tarun Sen | D13: =INDEX(Risk_Score!$D$8:$D$57, MATCH(6, Risk_Score!$O$8:$O$57, 0)) -> Divya Reddy | E13: =INDEX(Risk_Score!$C$8:$C$57, MATCH(6, Risk_Score!$O$8:$O$57, 0)) -> HR | F13: =INDEX(Risk_Score!$E$8:$E$57, MATCH(6, Risk_Score!$O$8:$O$57, 0)) -> 9 | G13: =INDEX(Risk_Score!$G$8:$G$57, MATCH(6, Risk_Score!$O$8:$O$57, 0)) -> 40-49 | H13: =INDEX(Risk_Score!$H$8:$H$57, MATCH(6, Risk_Score!$O$8:$O$57, 0)) -> 7 | I13: =INDEX(Risk_Score!$I$8:$I$57, MATCH(6, Risk_Score!$O$8:$O$57, 0)) -> 3 | J13: =INDEX(Risk_Score!$J$8:$J$57, MATCH(6, Risk_Score!$O$8:$O$57, 0)) -> 40 | K13: =INDEX(Risk_Score!$K$8:$K$57, MATCH(6, Risk_Score!$O$8:$O$57, 0)) -> 100 | L13: =INDEX(Risk_Score!$L$8:$L$57, MATCH(6, Risk_Score!$O$8:$O$57, 0)) -> 50 | M13: =INDEX(Risk_Score!$M$8:$M$57, MATCH(6, Risk_Score!$O$8:$O$57, 0)) -> 66.5 | N13: =INDEX(Risk_Score!$N$8:$N$57, MATCH(6, Risk_Score!$O$8:$O$57, 0)) -> Medium Risk
A14: 7 | B14: =INDEX(Risk_Score!$A$8:$A$57, MATCH(7, Risk_Score!$O$8:$O$57, 0)) -> EMP7284 | C14: =INDEX(Risk_Score!$B$8:$B$57, MATCH(7, Risk_Score!$O$8:$O$57, 0)) -> Amit Chakraborty | D14: =INDEX(Risk_Score!$D$8:$D$57, MATCH(7, Risk_Score!$O$8:$O$57, 0)) -> Siddharth Roy | E14: =INDEX(Risk_Score!$C$8:$C$57, MATCH(7, Risk_Score!$O$8:$O$57, 0)) -> HR | F14: =INDEX(Risk_Score!$E$8:$E$57, MATCH(7, Risk_Score!$O$8:$O$57, 0)) -> 15 | G14: =INDEX(Risk_Score!$G$8:$G$57, MATCH(7, Risk_Score!$O$8:$O$57, 0)) -> 40-49 | H14: =INDEX(Risk_Score!$H$8:$H$57, MATCH(7, Risk_Score!$O$8:$O$57, 0)) -> 10 | I14: =INDEX(Risk_Score!$I$8:$I$57, MATCH(7, Risk_Score!$O$8:$O$57, 0)) -> 1 | J14: =INDEX(Risk_Score!$J$8:$J$57, MATCH(7, Risk_Score!$O$8:$O$57, 0)) -> 0 | K14: =INDEX(Risk_Score!$K$8:$K$57, MATCH(7, Risk_Score!$O$8:$O$57, 0)) -> 100 | L14: =INDEX(Risk_Score!$L$8:$L$57, MATCH(7, Risk_Score!$O$8:$O$57, 0)) -> 100 | M14: =INDEX(Risk_Score!$M$8:$M$57, MATCH(7, Risk_Score!$O$8:$O$57, 0)) -> 65 | N14: =INDEX(Risk_Score!$N$8:$N$57, MATCH(7, Risk_Score!$O$8:$O$57, 0)) -> Medium Risk
A15: 8 | B15: =INDEX(Risk_Score!$A$8:$A$57, MATCH(8, Risk_Score!$O$8:$O$57, 0)) -> EMP6947 | C15: =INDEX(Risk_Score!$B$8:$B$57, MATCH(8, Risk_Score!$O$8:$O$57, 0)) -> Ritu Srivastava | D15: =INDEX(Risk_Score!$D$8:$D$57, MATCH(8, Risk_Score!$O$8:$O$57, 0)) -> Divya Reddy | E15: =INDEX(Risk_Score!$C$8:$C$57, MATCH(8, Risk_Score!$O$8:$O$57, 0)) -> Sales | F15: =INDEX(Risk_Score!$E$8:$E$57, MATCH(8, Risk_Score!$O$8:$O$57, 0)) -> 13 | G15: =INDEX(Risk_Score!$G$8:$G$57, MATCH(8, Risk_Score!$O$8:$O$57, 0)) -> 30-39 | H15: =INDEX(Risk_Score!$H$8:$H$57, MATCH(8, Risk_Score!$O$8:$O$57, 0)) -> 11 | I15: =INDEX(Risk_Score!$I$8:$I$57, MATCH(8, Risk_Score!$O$8:$O$57, 0)) -> 2 | J15: =INDEX(Risk_Score!$J$8:$J$57, MATCH(8, Risk_Score!$O$8:$O$57, 0)) -> 13.333333 | K15: =INDEX(Risk_Score!$K$8:$K$57, MATCH(8, Risk_Score!$O$8:$O$57, 0)) -> 100 | L15: =INDEX(Risk_Score!$L$8:$L$57, MATCH(8, Risk_Score!$O$8:$O$57, 0)) -> 75 | M15: =INDEX(Risk_Score!$M$8:$M$57, MATCH(8, Risk_Score!$O$8:$O$57, 0)) -> 63.4 | N15: =INDEX(Risk_Score!$N$8:$N$57, MATCH(8, Risk_Score!$O$8:$O$57, 0)) -> Medium Risk
A16: 9 | B16: =INDEX(Risk_Score!$A$8:$A$57, MATCH(9, Risk_Score!$O$8:$O$57, 0)) -> EMP2746 | C16: =INDEX(Risk_Score!$B$8:$B$57, MATCH(9, Risk_Score!$O$8:$O$57, 0)) -> Hema Rao | D16: =INDEX(Risk_Score!$D$8:$D$57, MATCH(9, Risk_Score!$O$8:$O$57, 0)) -> Divya Reddy | E16: =INDEX(Risk_Score!$C$8:$C$57, MATCH(9, Risk_Score!$O$8:$O$57, 0)) -> Finance | F16: =INDEX(Risk_Score!$E$8:$E$57, MATCH(9, Risk_Score!$O$8:$O$57, 0)) -> 13 | G16: =INDEX(Risk_Score!$G$8:$G$57, MATCH(9, Risk_Score!$O$8:$O$57, 0)) -> 50+ | H16: =INDEX(Risk_Score!$H$8:$H$57, MATCH(9, Risk_Score!$O$8:$O$57, 0)) -> 12 | I16: =INDEX(Risk_Score!$I$8:$I$57, MATCH(9, Risk_Score!$O$8:$O$57, 0)) -> 2 | J16: =INDEX(Risk_Score!$J$8:$J$57, MATCH(9, Risk_Score!$O$8:$O$57, 0)) -> 13.333333 | K16: =INDEX(Risk_Score!$K$8:$K$57, MATCH(9, Risk_Score!$O$8:$O$57, 0)) -> 100 | L16: =INDEX(Risk_Score!$L$8:$L$57, MATCH(9, Risk_Score!$O$8:$O$57, 0)) -> 75 | M16: =INDEX(Risk_Score!$M$8:$M$57, MATCH(9, Risk_Score!$O$8:$O$57, 0)) -> 63.4 | N16: =INDEX(Risk_Score!$N$8:$N$57, MATCH(9, Risk_Score!$O$8:$O$57, 0)) -> Medium Risk
A17: 10 | B17: =INDEX(Risk_Score!$A$8:$A$57, MATCH(10, Risk_Score!$O$8:$O$57, 0)) -> EMP2680 | C17: =INDEX(Risk_Score!$B$8:$B$57, MATCH(10, Risk_Score!$O$8:$O$57, 0)) -> Aarav Bose | D17: =INDEX(Risk_Score!$D$8:$D$57, MATCH(10, Risk_Score!$O$8:$O$57, 0)) -> Manish Tiwari | E17: =INDEX(Risk_Score!$C$8:$C$57, MATCH(10, Risk_Score!$O$8:$O$57, 0)) -> Marketing | F17: =INDEX(Risk_Score!$E$8:$E$57, MATCH(10, Risk_Score!$O$8:$O$57, 0)) -> 8 | G17: =INDEX(Risk_Score!$G$8:$G$57, MATCH(10, Risk_Score!$O$8:$O$57, 0)) -> 40-49 | H17: =INDEX(Risk_Score!$H$8:$H$57, MATCH(10, Risk_Score!$O$8:$O$57, 0)) -> 5 | I17: =INDEX(Risk_Score!$I$8:$I$57, MATCH(10, Risk_Score!$O$8:$O$57, 0)) -> 4 | J17: =INDEX(Risk_Score!$J$8:$J$57, MATCH(10, Risk_Score!$O$8:$O$57, 0)) -> 46.666667 | K17: =INDEX(Risk_Score!$K$8:$K$57, MATCH(10, Risk_Score!$O$8:$O$57, 0)) -> 100 | L17: =INDEX(Risk_Score!$L$8:$L$57, MATCH(10, Risk_Score!$O$8:$O$57, 0)) -> 25 | M17: =INDEX(Risk_Score!$M$8:$M$57, MATCH(10, Risk_Score!$O$8:$O$57, 0)) -> 62.6 | N17: =INDEX(Risk_Score!$N$8:$N$57, MATCH(10, Risk_Score!$O$8:$O$57, 0)) -> Medium Risk
A18: 11 | B18: =INDEX(Risk_Score!$A$8:$A$57, MATCH(11, Risk_Score!$O$8:$O$57, 0)) -> EMP7717 | C18: =INDEX(Risk_Score!$B$8:$B$57, MATCH(11, Risk_Score!$O$8:$O$57, 0)) -> Lata Tiwari | D18: =INDEX(Risk_Score!$D$8:$D$57, MATCH(11, Risk_Score!$O$8:$O$57, 0)) -> Manish Tiwari | E18: =INDEX(Risk_Score!$C$8:$C$57, MATCH(11, Risk_Score!$O$8:$O$57, 0)) -> Engineering | F18: =INDEX(Risk_Score!$E$8:$E$57, MATCH(11, Risk_Score!$O$8:$O$57, 0)) -> 8 | G18: =INDEX(Risk_Score!$G$8:$G$57, MATCH(11, Risk_Score!$O$8:$O$57, 0)) -> 40-49 | H18: =INDEX(Risk_Score!$H$8:$H$57, MATCH(11, Risk_Score!$O$8:$O$57, 0)) -> 7 | I18: =INDEX(Risk_Score!$I$8:$I$57, MATCH(11, Risk_Score!$O$8:$O$57, 0)) -> 4 | J18: =INDEX(Risk_Score!$J$8:$J$57, MATCH(11, Risk_Score!$O$8:$O$57, 0)) -> 46.666667 | K18: =INDEX(Risk_Score!$K$8:$K$57, MATCH(11, Risk_Score!$O$8:$O$57, 0)) -> 100 | L18: =INDEX(Risk_Score!$L$8:$L$57, MATCH(11, Risk_Score!$O$8:$O$57, 0)) -> 25 | M18: =INDEX(Risk_Score!$M$8:$M$57, MATCH(11, Risk_Score!$O$8:$O$57, 0)) -> 62.6 | N18: =INDEX(Risk_Score!$N$8:$N$57, MATCH(11, Risk_Score!$O$8:$O$57, 0)) -> Medium Risk
A19: 12 | B19: =INDEX(Risk_Score!$A$8:$A$57, MATCH(12, Risk_Score!$O$8:$O$57, 0)) -> EMP2124 | C19: =INDEX(Risk_Score!$B$8:$B$57, MATCH(12, Risk_Score!$O$8:$O$57, 0)) -> Hema Sinha | D19: =INDEX(Risk_Score!$D$8:$D$57, MATCH(12, Risk_Score!$O$8:$O$57, 0)) -> Sunita Bose | E19: =INDEX(Risk_Score!$C$8:$C$57, MATCH(12, Risk_Score!$O$8:$O$57, 0)) -> Sales | F19: =INDEX(Risk_Score!$E$8:$E$57, MATCH(12, Risk_Score!$O$8:$O$57, 0)) -> 4 | G19: =INDEX(Risk_Score!$G$8:$G$57, MATCH(12, Risk_Score!$O$8:$O$57, 0)) -> 30-39 | H19: =INDEX(Risk_Score!$H$8:$H$57, MATCH(12, Risk_Score!$O$8:$O$57, 0)) -> 3 | I19: =INDEX(Risk_Score!$I$8:$I$57, MATCH(12, Risk_Score!$O$8:$O$57, 0)) -> 3 | J19: =INDEX(Risk_Score!$J$8:$J$57, MATCH(12, Risk_Score!$O$8:$O$57, 0)) -> 73.333333 | K19: =INDEX(Risk_Score!$K$8:$K$57, MATCH(12, Risk_Score!$O$8:$O$57, 0)) -> 60 | L19: =INDEX(Risk_Score!$L$8:$L$57, MATCH(12, Risk_Score!$O$8:$O$57, 0)) -> 50 | M19: =INDEX(Risk_Score!$M$8:$M$57, MATCH(12, Risk_Score!$O$8:$O$57, 0)) -> 62.2 | N19: =INDEX(Risk_Score!$N$8:$N$57, MATCH(12, Risk_Score!$O$8:$O$57, 0)) -> Medium Risk
A20: 13 | B20: =INDEX(Risk_Score!$A$8:$A$57, MATCH(13, Risk_Score!$O$8:$O$57, 0)) -> EMP1106 | C20: =INDEX(Risk_Score!$B$8:$B$57, MATCH(13, Risk_Score!$O$8:$O$57, 0)) -> Kapil Pandey | D20: =INDEX(Risk_Score!$D$8:$D$57, MATCH(13, Risk_Score!$O$8:$O$57, 0)) -> Geeta Pillai | E20: =INDEX(Risk_Score!$C$8:$C$57, MATCH(13, Risk_Score!$O$8:$O$57, 0)) -> IT | F20: =INDEX(Risk_Score!$E$8:$E$57, MATCH(13, Risk_Score!$O$8:$O$57, 0)) -> 11 | G20: =INDEX(Risk_Score!$G$8:$G$57, MATCH(13, Risk_Score!$O$8:$O$57, 0)) -> 30-39 | H20: =INDEX(Risk_Score!$H$8:$H$57, MATCH(13, Risk_Score!$O$8:$O$57, 0)) -> 10 | I20: =INDEX(Risk_Score!$I$8:$I$57, MATCH(13, Risk_Score!$O$8:$O$57, 0)) -> 3 | J20: =INDEX(Risk_Score!$J$8:$J$57, MATCH(13, Risk_Score!$O$8:$O$57, 0)) -> 26.666667 | K20: =INDEX(Risk_Score!$K$8:$K$57, MATCH(13, Risk_Score!$O$8:$O$57, 0)) -> 100 | L20: =INDEX(Risk_Score!$L$8:$L$57, MATCH(13, Risk_Score!$O$8:$O$57, 0)) -> 50 | M20: =INDEX(Risk_Score!$M$8:$M$57, MATCH(13, Risk_Score!$O$8:$O$57, 0)) -> 61.8 | N20: =INDEX(Risk_Score!$N$8:$N$57, MATCH(13, Risk_Score!$O$8:$O$57, 0)) -> Medium Risk
A21: 14 | B21: =INDEX(Risk_Score!$A$8:$A$57, MATCH(14, Risk_Score!$O$8:$O$57, 0)) -> EMP4164 | C21: =INDEX(Risk_Score!$B$8:$B$57, MATCH(14, Risk_Score!$O$8:$O$57, 0)) -> Shreya Bhatia | D21: =INDEX(Risk_Score!$D$8:$D$57, MATCH(14, Risk_Score!$O$8:$O$57, 0)) -> Siddharth Roy | E21: =INDEX(Risk_Score!$C$8:$C$57, MATCH(14, Risk_Score!$O$8:$O$57, 0)) -> Marketing | F21: =INDEX(Risk_Score!$E$8:$E$57, MATCH(14, Risk_Score!$O$8:$O$57, 0)) -> 14 | G21: =INDEX(Risk_Score!$G$8:$G$57, MATCH(14, Risk_Score!$O$8:$O$57, 0)) -> 50+ | H21: =INDEX(Risk_Score!$H$8:$H$57, MATCH(14, Risk_Score!$O$8:$O$57, 0)) -> 10 | I21: =INDEX(Risk_Score!$I$8:$I$57, MATCH(14, Risk_Score!$O$8:$O$57, 0)) -> 2 | J21: =INDEX(Risk_Score!$J$8:$J$57, MATCH(14, Risk_Score!$O$8:$O$57, 0)) -> 6.6666667 | K21: =INDEX(Risk_Score!$K$8:$K$57, MATCH(14, Risk_Score!$O$8:$O$57, 0)) -> 100 | L21: =INDEX(Risk_Score!$L$8:$L$57, MATCH(14, Risk_Score!$O$8:$O$57, 0)) -> 75 | M21: =INDEX(Risk_Score!$M$8:$M$57, MATCH(14, Risk_Score!$O$8:$O$57, 0)) -> 61.1 | N21: =INDEX(Risk_Score!$N$8:$N$57, MATCH(14, Risk_Score!$O$8:$O$57, 0)) -> Medium Risk
A22: 15 | B22: =INDEX(Risk_Score!$A$8:$A$57, MATCH(15, Risk_Score!$O$8:$O$57, 0)) -> EMP2886 | C22: =INDEX(Risk_Score!$B$8:$B$57, MATCH(15, Risk_Score!$O$8:$O$57, 0)) -> Bhavna Kumar | D22: =INDEX(Risk_Score!$D$8:$D$57, MATCH(15, Risk_Score!$O$8:$O$57, 0)) -> Manish Tiwari | E22: =INDEX(Risk_Score!$C$8:$C$57, MATCH(15, Risk_Score!$O$8:$O$57, 0)) -> HR | F22: =INDEX(Risk_Score!$E$8:$E$57, MATCH(15, Risk_Score!$O$8:$O$57, 0)) -> 4 | G22: =INDEX(Risk_Score!$G$8:$G$57, MATCH(15, Risk_Score!$O$8:$O$57, 0)) -> 40-49 | H22: =INDEX(Risk_Score!$H$8:$H$57, MATCH(15, Risk_Score!$O$8:$O$57, 0)) -> 2 | I22: =INDEX(Risk_Score!$I$8:$I$57, MATCH(15, Risk_Score!$O$8:$O$57, 0)) -> 2 | J22: =INDEX(Risk_Score!$J$8:$J$57, MATCH(15, Risk_Score!$O$8:$O$57, 0)) -> 73.333333 | K22: =INDEX(Risk_Score!$K$8:$K$57, MATCH(15, Risk_Score!$O$8:$O$57, 0)) -> 40 | L22: =INDEX(Risk_Score!$L$8:$L$57, MATCH(15, Risk_Score!$O$8:$O$57, 0)) -> 75 | M22: =INDEX(Risk_Score!$M$8:$M$57, MATCH(15, Risk_Score!$O$8:$O$57, 0)) -> 60.4 | N22: =INDEX(Risk_Score!$N$8:$N$57, MATCH(15, Risk_Score!$O$8:$O$57, 0)) -> Medium Risk
A23: 16 | B23: =INDEX(Risk_Score!$A$8:$A$57, MATCH(16, Risk_Score!$O$8:$O$57, 0)) -> EMP1420 | C23: =INDEX(Risk_Score!$B$8:$B$57, MATCH(16, Risk_Score!$O$8:$O$57, 0)) -> Ritu Bose | D23: =INDEX(Risk_Score!$D$8:$D$57, MATCH(16, Risk_Score!$O$8:$O$57, 0)) -> Sunita Bose | E23: =INDEX(Risk_Score!$C$8:$C$57, MATCH(16, Risk_Score!$O$8:$O$57, 0)) -> IT | F23: =INDEX(Risk_Score!$E$8:$E$57, MATCH(16, Risk_Score!$O$8:$O$57, 0)) -> 9 | G23: =INDEX(Risk_Score!$G$8:$G$57, MATCH(16, Risk_Score!$O$8:$O$57, 0)) -> 30-39 | H23: =INDEX(Risk_Score!$H$8:$H$57, MATCH(16, Risk_Score!$O$8:$O$57, 0)) -> 8 | I23: =INDEX(Risk_Score!$I$8:$I$57, MATCH(16, Risk_Score!$O$8:$O$57, 0)) -> 4 | J23: =INDEX(Risk_Score!$J$8:$J$57, MATCH(16, Risk_Score!$O$8:$O$57, 0)) -> 40 | K23: =INDEX(Risk_Score!$K$8:$K$57, MATCH(16, Risk_Score!$O$8:$O$57, 0)) -> 100 | L23: =INDEX(Risk_Score!$L$8:$L$57, MATCH(16, Risk_Score!$O$8:$O$57, 0)) -> 25 | M23: =INDEX(Risk_Score!$M$8:$M$57, MATCH(16, Risk_Score!$O$8:$O$57, 0)) -> 60.3 | N23: =INDEX(Risk_Score!$N$8:$N$57, MATCH(16, Risk_Score!$O$8:$O$57, 0)) -> Medium Risk
A24: 17 | B24: =INDEX(Risk_Score!$A$8:$A$57, MATCH(17, Risk_Score!$O$8:$O$57, 0)) -> EMP1651 | C24: =INDEX(Risk_Score!$B$8:$B$57, MATCH(17, Risk_Score!$O$8:$O$57, 0)) -> Usha Joshi | D24: =INDEX(Risk_Score!$D$8:$D$57, MATCH(17, Risk_Score!$O$8:$O$57, 0)) -> Siddharth Roy | E24: =INDEX(Risk_Score!$C$8:$C$57, MATCH(17, Risk_Score!$O$8:$O$57, 0)) -> IT | F24: =INDEX(Risk_Score!$E$8:$E$57, MATCH(17, Risk_Score!$O$8:$O$57, 0)) -> 5 | G24: =INDEX(Risk_Score!$G$8:$G$57, MATCH(17, Risk_Score!$O$8:$O$57, 0)) -> 40-49 | H24: =INDEX(Risk_Score!$H$8:$H$57, MATCH(17, Risk_Score!$O$8:$O$57, 0)) -> 3 | I24: =INDEX(Risk_Score!$I$8:$I$57, MATCH(17, Risk_Score!$O$8:$O$57, 0)) -> 3 | J24: =INDEX(Risk_Score!$J$8:$J$57, MATCH(17, Risk_Score!$O$8:$O$57, 0)) -> 66.666667 | K24: =INDEX(Risk_Score!$K$8:$K$57, MATCH(17, Risk_Score!$O$8:$O$57, 0)) -> 60 | L24: =INDEX(Risk_Score!$L$8:$L$57, MATCH(17, Risk_Score!$O$8:$O$57, 0)) -> 50 | M24: =INDEX(Risk_Score!$M$8:$M$57, MATCH(17, Risk_Score!$O$8:$O$57, 0)) -> 59.8 | N24: =INDEX(Risk_Score!$N$8:$N$57, MATCH(17, Risk_Score!$O$8:$O$57, 0)) -> Medium Risk
A25: 18 | B25: =INDEX(Risk_Score!$A$8:$A$57, MATCH(18, Risk_Score!$O$8:$O$57, 0)) -> EMP4114 | C25: =INDEX(Risk_Score!$B$8:$B$57, MATCH(18, Risk_Score!$O$8:$O$57, 0)) -> Nikhil Singh | D25: =INDEX(Risk_Score!$D$8:$D$57, MATCH(18, Risk_Score!$O$8:$O$57, 0)) -> Geeta Pillai | E25: =INDEX(Risk_Score!$C$8:$C$57, MATCH(18, Risk_Score!$O$8:$O$57, 0)) -> IT | F25: =INDEX(Risk_Score!$E$8:$E$57, MATCH(18, Risk_Score!$O$8:$O$57, 0)) -> 15 | G25: =INDEX(Risk_Score!$G$8:$G$57, MATCH(18, Risk_Score!$O$8:$O$57, 0)) -> 50+ | H25: =INDEX(Risk_Score!$H$8:$H$57, MATCH(18, Risk_Score!$O$8:$O$57, 0)) -> 13 | I25: =INDEX(Risk_Score!$I$8:$I$57, MATCH(18, Risk_Score!$O$8:$O$57, 0)) -> 2 | J25: =INDEX(Risk_Score!$J$8:$J$57, MATCH(18, Risk_Score!$O$8:$O$57, 0)) -> 0 | K25: =INDEX(Risk_Score!$K$8:$K$57, MATCH(18, Risk_Score!$O$8:$O$57, 0)) -> 100 | L25: =INDEX(Risk_Score!$L$8:$L$57, MATCH(18, Risk_Score!$O$8:$O$57, 0)) -> 75 | M25: =INDEX(Risk_Score!$M$8:$M$57, MATCH(18, Risk_Score!$O$8:$O$57, 0)) -> 58.8 | N25: =INDEX(Risk_Score!$N$8:$N$57, MATCH(18, Risk_Score!$O$8:$O$57, 0)) -> Medium Risk
A26: 19 | B26: =INDEX(Risk_Score!$A$8:$A$57, MATCH(19, Risk_Score!$O$8:$O$57, 0)) -> EMP3344 | C26: =INDEX(Risk_Score!$B$8:$B$57, MATCH(19, Risk_Score!$O$8:$O$57, 0)) -> Suresh Krishnan | D26: =INDEX(Risk_Score!$D$8:$D$57, MATCH(19, Risk_Score!$O$8:$O$57, 0)) -> Geeta Pillai | E26: =INDEX(Risk_Score!$C$8:$C$57, MATCH(19, Risk_Score!$O$8:$O$57, 0)) -> Marketing | F26: =INDEX(Risk_Score!$E$8:$E$57, MATCH(19, Risk_Score!$O$8:$O$57, 0)) -> 9 | G26: =INDEX(Risk_Score!$G$8:$G$57, MATCH(19, Risk_Score!$O$8:$O$57, 0)) -> 30-39 | H26: =INDEX(Risk_Score!$H$8:$H$57, MATCH(19, Risk_Score!$O$8:$O$57, 0)) -> 4 | I26: =INDEX(Risk_Score!$I$8:$I$57, MATCH(19, Risk_Score!$O$8:$O$57, 0)) -> 3 | J26: =INDEX(Risk_Score!$J$8:$J$57, MATCH(19, Risk_Score!$O$8:$O$57, 0)) -> 40 | K26: =INDEX(Risk_Score!$K$8:$K$57, MATCH(19, Risk_Score!$O$8:$O$57, 0)) -> 80 | L26: =INDEX(Risk_Score!$L$8:$L$57, MATCH(19, Risk_Score!$O$8:$O$57, 0)) -> 50 | M26: =INDEX(Risk_Score!$M$8:$M$57, MATCH(19, Risk_Score!$O$8:$O$57, 0)) -> 58.5 | N26: =INDEX(Risk_Score!$N$8:$N$57, MATCH(19, Risk_Score!$O$8:$O$57, 0)) -> Medium Risk
A27: 20 | B27: =INDEX(Risk_Score!$A$8:$A$57, MATCH(20, Risk_Score!$O$8:$O$57, 0)) -> EMP5050 | C27: =INDEX(Risk_Score!$B$8:$B$57, MATCH(20, Risk_Score!$O$8:$O$57, 0)) -> Naveen Chauhan | D27: =INDEX(Risk_Score!$D$8:$D$57, MATCH(20, Risk_Score!$O$8:$O$57, 0)) -> Sunita Bose | E27: =INDEX(Risk_Score!$C$8:$C$57, MATCH(20, Risk_Score!$O$8:$O$57, 0)) -> Legal | F27: =INDEX(Risk_Score!$E$8:$E$57, MATCH(20, Risk_Score!$O$8:$O$57, 0)) -> 6 | G27: =INDEX(Risk_Score!$G$8:$G$57, MATCH(20, Risk_Score!$O$8:$O$57, 0)) -> 40-49 | H27: =INDEX(Risk_Score!$H$8:$H$57, MATCH(20, Risk_Score!$O$8:$O$57, 0)) -> 3 | I27: =INDEX(Risk_Score!$I$8:$I$57, MATCH(20, Risk_Score!$O$8:$O$57, 0)) -> 3 | J27: =INDEX(Risk_Score!$J$8:$J$57, MATCH(20, Risk_Score!$O$8:$O$57, 0)) -> 60 | K27: =INDEX(Risk_Score!$K$8:$K$57, MATCH(20, Risk_Score!$O$8:$O$57, 0)) -> 60 | L27: =INDEX(Risk_Score!$L$8:$L$57, MATCH(20, Risk_Score!$O$8:$O$57, 0)) -> 50 | M27: =INDEX(Risk_Score!$M$8:$M$57, MATCH(20, Risk_Score!$O$8:$O$57, 0)) -> 57.5 | N27: =INDEX(Risk_Score!$N$8:$N$57, MATCH(20, Risk_Score!$O$8:$O$57, 0)) -> Medium Risk

Sheet Dash_board
A1: HR Attrition Risk Dashboard | Top 10 At-Risk Employees
C3: Total Employee | F3: High Risk (>=70) | I3: Medium Risk (45 - 69) | L3: Low Risk (>45) | O3: Avg Risk Score
C4: =COUNTA(Risk_Score!B7:B56) -> 50 | F4: =COUNTIF(Risk_Score!N8:N57, "High Risk") -> 2 | I4: =COUNTIF(Risk_Score!N8:N57, "Medium Risk") -> 42 | L4: =COUNTIF(Risk_Score!N8:N57, "Low Risk") -> 6 | O4: =AVERAGE(Risk_Score!M8:M57) -> 55.136
